<?xml version="1.0" encoding="utf-8"?>
<!-- This URDF was automatically created by SolidWorks to URDF Exporter! Originally created by Stephen Brawner (brawner@gmail.com) 
     Commit Version: 1.6.0-1-g15f4949  Build Version: 1.6.7594.29634
     For more information, please see http://wiki.ros.org/sw_urdf_exporter -->
<robot
  name="RRR">
  <link
    name="base_link">
    <inertial>
      <origin
        xyz="-9.5748E-19 -3.3818E-35 0.007"
        rpy="0 0 0" />
      <mass
        value="0.015708" />
      <inertia
        ixx="1.7174E-06"
        ixy="-4.6079E-39"
        ixz="2.7975E-23"
        iyy="1.7174E-06"
        iyz="-3.8703E-39"
        izz="2.6704E-06" />
    </inertial>
    <visual>
      <origin
        xyz="0 0 0"
        rpy="0 0 0" />
      <geometry>
        <mesh
          filename="package://RRR/meshes/base_link.STL" />
      </geometry>
      <material
        name="">
        <color
          rgba="0.79216 0.81961 0.93333 1" />
      </material>
    </visual>
    <collision>
      <origin
        xyz="0 0 0"
        rpy="0 0 0" />
      <geometry>
        <mesh
          filename="package://RRR/meshes/base_link.STL" />
      </geometry>
    </collision>
  </link>
  <link
    name="link1">
    <inertial>
      <origin
        xyz="0.06 1.6572E-17 0.005"
        rpy="0 0 0" />
      <mass
        value="0.054283" />
      <inertia
        ixx="7.9519E-06"
        ixy="-2.7928E-20"
        ixz="-1.8917E-20"
        iyy="9.4571E-05"
        iyz="6.1709E-22"
        izz="0.00010162" />
    </inertial>
    <visual>
      <origin
        xyz="0 0 0"
        rpy="0 0 0" />
      <geometry>
        <mesh
          filename="package://RRR/meshes/link1.STL" />
      </geometry>
      <material
        name="">
        <color
          rgba="0.79216 0.81961 0.93333 1" />
      </material>
    </visual>
    <collision>
      <origin
        xyz="0 0 0"
        rpy="0 0 0" />
      <geometry>
        <mesh
          filename="package://RRR/meshes/link1.STL" />
      </geometry>
    </collision>
  </link>
  <joint
    name="joint1"
    type="continuous">
    <origin
      xyz="0 0 0.01"
      rpy="0 0 0" />
    <parent
      link="base_link" />
    <child
      link="link1" />
    <axis
      xyz="0 0 1" />
  </joint>
  <link
    name="link2">
    <inertial>
      <origin
        xyz="0.06 4.0737E-17 -0.005"
        rpy="0 0 0" />
      <mass
        value="0.054283" />
      <inertia
        ixx="7.9519E-06"
        ixy="-2.3521E-20"
        ixz="-8.4584E-20"
        iyy="9.4571E-05"
        iyz="-6.0223E-22"
        izz="0.00010162" />
    </inertial>
    <visual>
      <origin
        xyz="0 0 0"
        rpy="0 0 0" />
      <geometry>
        <mesh
          filename="package://RRR/meshes/link2.STL" />
      </geometry>
      <material
        name="">
        <color
          rgba="0.79216 0.81961 0.93333 1" />
      </material>
    </visual>
    <collision>
      <origin
        xyz="0 0 0"
        rpy="0 0 0" />
      <geometry>
        <mesh
          filename="package://RRR/meshes/link2.STL" />
      </geometry>
    </collision>
  </link>
  <joint
    name="joint2"
    type="continuous">
    <origin
      xyz="0.12 0 0"
      rpy="0 0 0" />
    <parent
      link="link1" />
    <child
      link="link2" />
    <axis
      xyz="0 0 1" />
  </joint>
  <link
    name="link3">
    <inertial>
      <origin
        xyz="0.06 6.661E-17 0.005"
        rpy="0 0 0" />
      <mass
        value="0.054283" />
      <inertia
        ixx="7.9519E-06"
        ixy="-1.8727E-20"
        ixz="-1.644E-19"
        iyy="9.4571E-05"
        iyz="-1.3312E-21"
        izz="0.00010162" />
    </inertial>
    <visual>
      <origin
        xyz="0 0 0"
        rpy="0 0 0" />
      <geometry>
        <mesh
          filename="package://RRR/meshes/link3.STL" />
      </geometry>
      <material
        name="">
        <color
          rgba="0.79216 0.81961 0.93333 1" />
      </material>
    </visual>
    <collision>
      <origin
        xyz="0 0 0"
        rpy="0 0 0" />
      <geometry>
        <mesh
          filename="package://RRR/meshes/link3.STL" />
      </geometry>
    </collision>
  </link>
  <joint
    name="joint3"
    type="continuous">
    <origin
      xyz="0.12 0 0"
      rpy="0 0 0" />
    <parent
      link="link2" />
    <child
      link="link3" />
    <axis
      xyz="0 0 1" />
  </joint>
</robot>